{
  "id": "ch_C0516UPPMT3_2023-06-20_1687279700.283609_thread",
  "type": "channel",
  "channel_name": "aihub-feedback",
  "conversation_type": "thread",
  "participants": [
    "joshbronko",
    "Serena"
  ],
  "messages": [
    {
      "sender": "joshbronko",
      "user_id": "U031T0PNLUS",
      "message": "Any idea why i am getting this when calling run_sync\n```{\n    \"model_name\": \"ibllm\",\n    \"model_version\": \"1.1.13\",\n    \"model_payload\": {\n        \"custom_request\": {\n            \"task\": \"extraction\",\n            \"fields\": [\n                {\n                    \"name\": \"d-dddd\",\n                    \"prompt\": \"Employee Name\",\n                    \"type\": \"basic\"\n                }\n            ],\n            \"skip_indexing\": true\n        }\n    },\n    \"input_path\": \"josh.bronikowski/my-repo/fs/Instabase Drive/ibhack6/292092612907/intuit1.pdf.ibdoc\"\n}```\n\n```{\n    \"start_time\": 1687279600.0,\n    \"end_time\": 1687279600.0,\n    \"model_result\": {\n        \"custom_result\": {\n            \"token_usage_stats\": [\n                {\n                    \"model_name\": \"gpt-3.5-turbo\",\n                    \"completion_tokens\": 11.0,\n                    \"total_tokens\": 443.0,\n                    \"prompt_tokens\": 432.0\n                }\n            ],\n            \"error\": \"Exception in Provenance: list index out of range\",\n            \"is_long_doc\": false,\n            \"fields\": {}\n        }\n    },\n    \"message\": \"Error during model run.\"\n}```",
      "time": "09:48",
      "timestamp": "1687279700.283609",
      "is_reply": false
    },
    {
      "sender": "Serena",
      "user_id": "U01CZ3LBFU4",
      "message": "seems like an error message from our logic for parsing the modelâ€™s response\n\ncc @Kathy Wu",
      "time": "10:15",
      "timestamp": "1687281345.360969",
      "is_reply": true
    },
    {
      "sender": "joshbronko",
      "user_id": "U031T0PNLUS",
      "message": "@Serena i found this is actually a result of this issue from this thread https://instabase.slack.com/archives/C02KS5FHZEE/p1687281619835379",
      "time": "11:12",
      "timestamp": "1687284754.672319",
      "is_reply": true
    },
    {
      "sender": "joshbronko",
      "user_id": "U031T0PNLUS",
      "message": "I created an ibdoc on 23.04.16 and 23.04.02 and this error went away",
      "time": "11:12",
      "timestamp": "1687284777.570409",
      "is_reply": true
    },
    {
      "sender": "Serena",
      "user_id": "U01CZ3LBFU4",
      "message": "ah i see, thanks for starting the other thread!",
      "time": "11:46",
      "timestamp": "1687286806.649179",
      "is_reply": true
    }
  ],
  "metadata": {
    "channel_id": "C0516UPPMT3",
    "channel_name": "aihub-feedback",
    "date_file": "2023-06-20.json",
    "message_count": 5,
    "start_time": "1687279700.283609",
    "end_time": "1687286806.649179",
    "is_thread": true
  }
}