{
  "id": "ch_C06FA6A23_2019-11-25_1574736569.031500_thread",
  "type": "channel",
  "channel_name": "discuss-engineering",
  "conversation_type": "thread",
  "participants": [
    "Aaron Vontell",
    "Chetan"
  ],
  "messages": [
    {
      "sender": "Aaron Vontell",
      "user_id": "UCWNLU6CB",
      "message": "Following the dev setup docs, I get the following error when attempting to run tests:\n\n```ERROR MESSAGE: b'Traceback (most recent call last):\\n  File \"/Users/aaronvontell/.pyenv/versions/3.7.3/bin/mypy\", line 6, in <module>\\n    from mypy.__main__ import console_entry\\n  File \"/Users/aaronvontell/.pyenv/versions/3.7.3/lib/python3.7/site-packages/mypy/__main__.py\", line 3, in <module>\\n    from mypy.main import main\\n  File \"/Users/aaronvontell/.pyenv/versions/3.7.3/lib/python3.7/site-packages/mypy/main.py\", line 14, in <module>\\n    from mypy import build\\n  File \"mypy/build.py\", line 35, in <module>\\n  File \"mypy/nodes.py\", line 9, in <module>\\nAttributeError: module \\'mypy_extensions\\' has no attribute \\'trait\\'\\n'\nSTDOUT:\nmake[1]: *** [mypy-unit-tests] Error 1\nmake: *** [run-test-local] Error 2```",
      "time": "18:49",
      "timestamp": "1574736569.031500",
      "is_reply": false
    },
    {
      "sender": "Chetan",
      "user_id": "UE3TJAR9U",
      "message": "Don't use a venv",
      "time": "21:59",
      "timestamp": "1574747981.032200",
      "is_reply": true
    },
    {
      "sender": "Chetan",
      "user_id": "UE3TJAR9U",
      "message": "I got this error using a venv and a pyenv when I only needed a pyenv",
      "time": "22:01",
      "timestamp": "1574748087.032500",
      "is_reply": true
    }
  ],
  "metadata": {
    "channel_id": "C06FA6A23",
    "channel_name": "discuss-engineering",
    "date_file": "2019-11-25.json",
    "message_count": 3,
    "start_time": "1574736569.031500",
    "end_time": "1574748087.032500",
    "is_thread": true
  }
}