{
  "id": "ch_C06FA6A23_2023-02-09_1675976451.463479_thread",
  "type": "channel",
  "channel_name": "discuss-engineering",
  "conversation_type": "thread",
  "participants": [
    "lenny",
    "pauline.comising"
  ],
  "messages": [
    {
      "sender": "pauline.comising",
      "user_id": "U03TWMC0T24",
      "message": "Hey team, when running `make test COVERAGE=True OPEN_REPORT=True`, I've been getting the following mypy errors\n```TYPECHECKING FAILURE: mypy exited with code 1\n/Users/acomis/Desktop/WorkRepos/instabase/shared-utils/py-utils/typing-utils/src/py/stubs/instabase/protos/flow/flow_results_pb2.pyi:2: error: Library stubs not installed for \"google.protobuf.descriptor\" (or incompatible with Python 3.7)\ninstabase/solution_utils/marketplace.py:15: error: Library stubs not installed for \"requests\" (or incompatible with Python 3.7)\ninstabase/solution_utils/marketplace.py:15: note: Hint: \"python3 -m pip install types-requests\"```\nusing `pyenv global 3.9.15` doesnt seem to change the output, nor does using the hinted command. Does anyone know how to fix this?",
      "time": "13:00",
      "timestamp": "1675976451.463479",
      "is_reply": false
    },
    {
      "sender": "lenny",
      "user_id": "U02BTGKFVAR",
      "message": "what folder are you running tests from?",
      "time": "13:01",
      "timestamp": "1675976500.024919",
      "is_reply": true
    },
    {
      "sender": "pauline.comising",
      "user_id": "U03TWMC0T24",
      "message": "`shared-utils/py-utils/solution-utils`",
      "time": "13:02",
      "timestamp": "1675976526.077119",
      "is_reply": true
    },
    {
      "sender": "lenny",
      "user_id": "U02BTGKFVAR",
      "message": "what does `mypy --version` get you? also do you get the same error with just `make test` (no coverage/open_report)?",
      "time": "13:02",
      "timestamp": "1675976551.152239",
      "is_reply": true
    },
    {
      "sender": "pauline.comising",
      "user_id": "U03TWMC0T24",
      "message": "`mypy 0.981 (compiled: no)` and yep yep the error is the same",
      "time": "13:04",
      "timestamp": "1675976648.511539",
      "is_reply": true
    },
    {
      "sender": "lenny",
      "user_id": "U02BTGKFVAR",
      "message": "ah, that's too new â€” try `pip install mypy==0.701` (and make sure you are back on python 3.7)",
      "time": "13:04",
      "timestamp": "1675976675.326559",
      "is_reply": true
    },
    {
      "sender": "pauline.comising",
      "user_id": "U03TWMC0T24",
      "message": "ahh tyvm, that worked :,)",
      "time": "13:10",
      "timestamp": "1675977018.167559",
      "is_reply": true
    }
  ],
  "metadata": {
    "channel_id": "C06FA6A23",
    "channel_name": "discuss-engineering",
    "date_file": "2023-02-09.json",
    "message_count": 7,
    "start_time": "1675976451.463479",
    "end_time": "1675977018.167559",
    "is_thread": true
  }
}