{
  "id": "ch_C05L87V014J_2024-10-27_1730083266.508869_thread",
  "type": "channel",
  "channel_name": "ask-crafting",
  "conversation_type": "thread",
  "participants": [
    "Alapan",
    "Serena",
    "Sayd"
  ],
  "messages": [
    {
      "sender": "Sayd",
      "user_id": "U03F7QMAU8N",
      "message": "Is anyone else experiencing broken tunnels over the weekend?\n\n```sudo sh -c \"CRAFTING_SANDBOX_SERVER_URL=https://instabase.sandboxes.site cs pf -P -F -L 80:dev:80 -L 8600:localhost:8600 -W  sayd-dev/dev\"\nPassword:\nâœ” select the only one - instabase\nLOCAL          DIR REMOTE         STATE   #CONN LAST-ERROR/DETAILS\n127.0.0.1:80   ==> dev:80         RUNNING     2 Unknown: dial tcp 169.254.16.1:80: connect: connection refused\n127.0.0.1:8600 ==> localhost:8600 RUNNING\nShutting down ...```",
      "time": "19:41",
      "timestamp": "1730083266.508869",
      "is_reply": false
    },
    {
      "sender": "Sayd",
      "user_id": "U03F7QMAU8N",
      "message": "And when I try to log in to ppy-server-nginx link (https://ppy-server-nginx--sayd-dev-instabase.instabase.site.sandboxes.run/), it just hangs on auth step (either login with email or google oath)",
      "time": "19:42",
      "timestamp": "1730083379.141139",
      "is_reply": true
    },
    {
      "sender": "Serena",
      "user_id": "U01CZ3LBFU4",
      "message": "for the auth issue, do you see any relevant error logs in `webapp` or `core-platform-service`?",
      "time": "21:14",
      "timestamp": "1730088887.238009",
      "is_reply": true
    },
    {
      "sender": "Alapan",
      "user_id": "U056NM5QYTX",
      "message": "I had a similar issue due to `webapp` not being up",
      "time": "22:17",
      "timestamp": "1730092646.953319",
      "is_reply": true
    }
  ],
  "metadata": {
    "channel_id": "C05L87V014J",
    "channel_name": "ask-crafting",
    "date_file": "2024-10-27.json",
    "message_count": 4,
    "start_time": "1730083266.508869",
    "end_time": "1730092646.953319",
    "is_thread": true
  }
}