{
  "id": "ch_C06FA6A23_2025-03-28_1743165814.017789_thread",
  "type": "channel",
  "channel_name": "discuss-engineering",
  "conversation_type": "thread",
  "participants": [
    "Cody Boggs",
    "anshul.padhi",
    "lydia"
  ],
  "messages": [
    {
      "sender": "anshul.padhi",
      "user_id": "U084V5XTMFT",
      "message": "Had the same error, rerunning it fixed it for me",
      "time": "05:43",
      "timestamp": "1743165814.017789",
      "is_reply": false
    },
    {
      "sender": "Cody Boggs",
      "user_id": "U037PKN4USZ",
      "message": "Hmm how odd\nI thought for a moment yesterday that the failing runs were all on the same node perhaps but that didn’t seem to be the case",
      "time": "06:27",
      "timestamp": "1743168477.122629",
      "is_reply": true
    },
    {
      "sender": "lydia",
      "user_id": "UJK4LKYSJ",
      "message": "@Cody Boggs we see this error and it’s the main cause of flaky CI tests, as far as I know. It’s not in the same python package, but always this error message about missing file / directory. I created a ticket in platform eng’s Jira for it with a few ci run examples a few months back. I think fixing this flakiness would greatly improve the reliability of CI runs",
      "time": "06:38",
      "timestamp": "1743169090.720089",
      "is_reply": true
    },
    {
      "sender": "Cody Boggs",
      "user_id": "U037PKN4USZ",
      "message": "Interesting, okie doke. I'll have the team take a look and we'll see if we can find a fix :slightly_smiling_face:",
      "time": "06:43",
      "timestamp": "1743169385.083979",
      "is_reply": true
    }
  ],
  "metadata": {
    "channel_id": "C06FA6A23",
    "channel_name": "discuss-engineering",
    "date_file": "2025-03-28.json",
    "message_count": 4,
    "start_time": "1743165814.017789",
    "end_time": "1743169385.083979",
    "is_thread": true
  }
}