{
  "id": "ch_C06FA6A23_2023-01-10_1673363686.521209_thread",
  "type": "channel",
  "channel_name": "discuss-engineering",
  "conversation_type": "thread",
  "participants": [
    "Adam",
    "lenny"
  ],
  "messages": [
    {
      "sender": "Adam",
      "user_id": "U028KUTFHBR",
      "message": "I can run apps-server fine, but api-server-apps has a lot of errors in the first run. Was the api-server-apps migration recent?\n```• Installing pdfminer-six (20221210 47baa0d): Failed\n\n  PermissionError\n\n  [Errno 13] Permission denied: '/Users/adamlipson/Library/Caches/pypoetry/virtualenvs/api-server-apps-Sza10wTU-py3.9/src/pdfminer.six.public/.git/objects/pack'\n\n  at ~/Library/Application Support/pypoetry/venv/lib/python3.7/site-packages/dulwich/object_store.py:703 in _update_pack_cache\n       699│ \n       700│     def _update_pack_cache(self):\n       701│         \"\"\"Read and iterate over new pack files and cache them.\"\"\"\n       702│         try:\n    →  703│             pack_dir_contents = os.listdir(self.pack_dir)\n       704│         except FileNotFoundError:\n       705│             self.close()```",
      "time": "07:14",
      "timestamp": "1673363686.521209",
      "is_reply": false
    },
    {
      "sender": "lenny",
      "user_id": "U02BTGKFVAR",
      "message": "it was around dec 30 iirc, i think this is related to the migration. there’s a sporadic bug with poetry that causes the venv to be corrupted like this, I’m testing a fix and should have it in today — in the meantime you can run via docker",
      "time": "07:17",
      "timestamp": "1673363851.021229",
      "is_reply": true
    }
  ],
  "metadata": {
    "channel_id": "C06FA6A23",
    "channel_name": "discuss-engineering",
    "date_file": "2023-01-10.json",
    "message_count": 2,
    "start_time": "1673363686.521209",
    "end_time": "1673363851.021229",
    "is_thread": true
  }
}